Workbook
Name Slicer_time_category: #N/A
Name Slicer_weather_type: #N/A

Sheet Dataset3
A1: instant | B1: dteday | C1: season | D1: yr | E1: mnth | F1: hr | G1: holiday | H1: weekday | I1: weathersit | J1: temp | K1: atemp | L1: hum | M1: windspeed | N1: casual | O1: registered | P1: cnt
A2: 620 | B2: 40572 | C2: 1 | D2: 0 | E2: 1 | F2: 1 | G2: FALSE | H2: 6 | I2: 1 | J2: 0.22 | K2: 0.2273 | L2: 0.64 | M2: 0.194 | N2: 0 | O2: 20 | P2: 20
A3: 621 | B3: 40572 | C3: 1 | D3: 0 | E3: 1 | F3: 2 | G3: FALSE | H3: 6 | I3: 1 | J3: 0.22 | K3: 0.2273 | L3: 0.64 | M3: 0.1642 | N3: 0 | O3: 15 | P3: 15
A4: 622 | B4: 40572 | C4: 1 | D4: 0 | E4: 1 | F4: 3 | G4: FALSE | H4: 6 | I4: 1 | J4: 0.2 | K4: 0.2121 | L4: 0.64 | M4: 0.1343 | N4: 3 | O4: 5 | P4: 8
A5: 623 | B5: 40572 | C5: 1 | D5: 0 | E5: 1 | F5: 4 | G5: FALSE | H5: 6 | I5: 1 | J5: 0.16 | K5: 0.1818 | L5: 0.69 | M5: 0.1045 | N5: 1 | O5: 2 | P5: 3
A6: 624 | B6: 40572 | C6: 1 | D6: 0 | E6: 1 | F6: 6 | G6: FALSE | H6: 6 | I6: 1 | J6: 0.16 | K6: 0.1818 | L6: 0.64 | M6: 0.1343 | N6: 0 | O6: 2 | P6: 2
A7: 625 | B7: 40572 | C7: 1 | D7: 0 | E7: 1 | F7: 7 | G7: FALSE | H7: 6 | I7: 1 | J7: 0.16 | K7: 0.1818 | L7: 0.59 | M7: 0.1045 | N7: 1 | O7: 4 | P7: 5
A8: 626 | B8: 40572 | C8: 1 | D8: 0 | E8: 1 | F8: 8 | G8: FALSE | H8: 6 | I8: 1 | J8: 0.18 | K8: 0.197 | L8: 0.55 | M8: 0.1642 | N8: 3 | O8: 31 | P8: 34
A9: 627 | B9: 40572 | C9: 1 | D9: 0 | E9: 1 | F9: 9 | G9: FALSE | H9: 6 | I9: 1 | J9: 0.18 | K9: 0.2121 | L9: 0.59 | M9: 0.0896 | N9: 0 | O9: 34 | P9: 34
A10: 628 | B10: 40572 | C10: 1 | D10: 0 | E10: 1 | F10: 10 | G10: FALSE | H10: 6 | I10: 2 | J10: 0.18 | K10: 0.2121 | L10: 0.64 | M10: 0.1045 | N10: 4 | O10: 51 | P10: 55
A11: 629 | B11: 40572 | C11: 1 | D11: 0 | E11: 1 | F11: 11 | G11: FALSE | H11: 6 | I11: 2 | J11: 0.18 | K11: 0.197 | L11: 0.64 | M11: 0.1343 | N11: 4 | O11: 60 | P11: 64
A12: 630 | B12: 40572 | C12: 1 | D12: 0 | E12: 1 | F12: 12 | G12: FALSE | H12: 6 | I12: 2 | J12: 0.2 | K12: 0.197 | L12: 0.59 | M12: 0.194 | N12: 12 | O12: 66 | P12: 78
A13: 631 | B13: 40572 | C13: 1 | D13: 0 | E13: 1 | F13: 13 | G13: FALSE | H13: 6 | I13: 2 | J13: 0.22 | K13: 0.2273 | L13: 0.55 | M13: 0.1642 | N13: 9 | O13: 56 | P13: 65
... A391: 619 | B391: 40572 | C391: 1 | D391: 0 | E391: 1 | F391: 0 | G391: FALSE | H391: 6 | I391: 1 | J391: 0.22 | K391: 0.197 | L391: 0.64 | M391: 0.3582 | N391: 2 | O391: 26 | P391: 28

Sheet Dataset2
A1: Unnamed: 0 | B1: instant | C1: atemp | D1: hum | E1: windspeed | F1: casual | G1: registered | H1: cnt
A2: 0 | B2: 1 | C2: 0.2879 | D2: 0.81 | E2: 0 | F2: 3 | G2: 13 | H2: 16
A3: 1 | B3: 2 | C3: 0.2727 | D3: 0.8 | E3: 0 | F3: 8 | G3: 32 | H3: 40
A4: 2 | B4: 3 | C4: 0.2727 | D4: 0.8 | E4: 0 | F4: 5 | G4: 27 | H4: 32
A5: 3 | B5: 4 | C5: 0.2879 | D5: 0.75 | E5: 0 | F5: 3 | G5: 10 | H5: 13
A6: 4 | B6: 5 | C6: 0.2879 | D6: 0.75 | E6: 0 | F6: 0 | G6: 1 | H6: 1
A7: 5 | B7: 6 | C7: 0.2576 | D7: 0.75 | E7: 0.0896 | F7: 0 | G7: 1 | H7: 1
A8: 6 | B8: 7 | C8: 0.2727 | D8: 0.8 | E8: 0 | F8: 2 | G8: 0 | H8: 2
A9: 7 | B9: 8 | C9: 0.2576 | D9: 0.86 | E9: 0 | F9: 1 | G9: 2 | H9: 3
A10: 8 | B10: 9 | D10: 0.75 | E10: 0 | F10: 1 | G10: 7 | H10: 8
A11: 9 | B11: 10 | C11: 0.3485 | D11: 0.76 | E11: 0 | F11: 8 | G11: 6 | H11: 14
A12: 10 | B12: 11 | C12: 0.3939 | D12: 0.76 | E12: 0.2537 | F12: 12 | G12: 24 | H12: 36
A13: 11 | B13: 12 | C13: 0.3333 | D13: 0.81 | E13: 0.2836 | F13: 26 | G13: 30 | H13: 56
A14: 12 | B14: 13 | C14: 0.4242 | D14: 0.77 | E14: 0.2836 | F14: 29 | G14: 55 | H14: 84
A15: 13 | B15: 14 | C15: 0.4545 | D15: 0.72 | E15: 0.2985 | F15: 47 | G15: 47 | H15: 94
A16: 14 | B16: 15 | C16: 0.4545 | D16: 0.72 | E16: 0.2836 | F16: 35 | G16: 71 | H16: 106
A17: 15 | B17: 16 | C17: 0.4394 | D17: 0.77 | E17: 0.2985 | F17: 40 | G17: 70 | H17: 110
A18: 16 | B18: 17 | C18: 0.4242 | D18: 0.82 | E18: 0.2985 | F18: 41 | G18: 52 | H18: 93
A19: 17 | B19: 18 | D19: 0.82 | E19: 0.2836 | F19: 15 | G19: 52 | H19: 67
A20: 18 | B20: 19 | C20: 0.4242 | D20: 0.88 | E20: 0.2537 | F20: 9 | G20: 26 | H20: 35
A21: 19 | B21: 20 | C21: 0.4242 | D21: 0.88 | E21: 0.2537 | F21: 6 | G21: 31 | H21: 37
A22: 20 | B22: 21 | C22: 0.4091 | D22: 0.87 | E22: 0.2537 | F22: 11 | G22: 25 | H22: 36
A23: 21 | B23: 22 | C23: 0.4091 | D23: 0.87 | E23: 0.194 | F23: 3 | G23: 31 | H23: 34
A24: 22 | B24: 23 | C24: 0.4091 | D24: 0.94 | E24: 0.2239 | F24: 11 | G24: 17 | H24: 28
A25: 23 | B25: 24 | D25: 0.88 | E25: 0.2985 | F25: 15 | G25: 24 | H25: 39
A26: 24 | B26: 25 | C26: 0.4545 | D26: 0.88 | E26: 0.2985 | F26: 4 | G26: 13 | H26: 17
A27: 25 | B27: 26 | C27: 0.4394 | D27: 0.94 | E27: 0.2537 | F27: 1 | G27: 16 | H27: 17
A28: 26 | B28: 27 | C28: 0.4242 | D28: 1 | E28: 0.2836 | F28: 1 | G28: 8 | H28: 9
A29: 27 | B29: 28 | C29: 0.4545 | D29: 0.94 | E29: 0.194 | F29: 2 | G29: 4 | H29: 6
A30: 28 | B30: 29 | D30: 0.94 | E30: 0.194 | F30: 2 | G30: 1 | H30: 3
A31: 29 | B31: 30 | C31: 0.4242 | D31: 0.77 | E31: 0.2985 | F31: 0 | G31: 2 | H31: 2
A32: 30 | B32: 31 | C32: 0.4091 | D32: 0.76 | E32: 0.194 | F32: 0 | G32: 1 | H32: 1
A33: 31 | B33: 32 | C33: 0.4091 | D33: 0.71 | E33: 0.2239 | F33: 0 | G33: 8 | H33: 8
A34: 32 | B34: 33 | D34: 0.76 | E34: 0.2239 | F34: 1 | G34: 19 | H34: 20
A35: 33 | B35: 34 | C35: 0.3485 | D35: 0.81 | E35: 0.2239 | F35: 7 | G35: 46 | H35: 53
A36: 34 | B36: 35 | C36: 0.3333 | D36: 0.71 | E36: 0.2537 | F36: 16 | G36: 54 | H36: 70
A37: 35 | B37: 36 | C37: 0.3333 | D37: 0.66 | E37: 0.2985 | F37: 20 | G37: 73 | H37: 93
A38: 36 | B38: 37 | C38: 0.3485 | D38: 0.66 | E38: 0.1343 | F38: 11 | G38: 64 | H38: 75
A39: 37 | B39: 38 | D39: 0.76 | E39: 0.194 | F39: 4 | G39: 55 | H39: 59
A40: 38 | B40: 39 | C40: 0.3333 | D40: 0.81 | E40: 0.1642 | F40: 19 | G40: 55 | H40: 74
...

Sheet Sheet4
A3: Row Labels
A4: Afternoon
A5: Evening
A6: Morning
A7: Grand Total

Sheet Sheet5
A3: Sum of cnt | B3: Column Labels
A4: Row Labels | B4: Clear | C4: cloudy | D4: Heavy Rain | E4: Rain | F4: Grand Total
A5: Afternoon | B5: 9372 | C5: 4699 | D5: 26 | E5: 511 | F5: 14608
A6: Evening | B6: 4690 | C6: 1583 | E6: 311 | F6: 6584
A7: Morning | B7: 8077 | C7: 4063 | E7: 550 | F7: 12690
A8: Grand Total | B8: 22139 | C8: 10345 | D8: 26 | E8: 1372 | F8: 33882

Sheet Dashboard
H1: Bike Rental Dashboard
C2: CHART 1 | M2: CHART 2
S8: InSights:
S9: CHART 1:Peak usage in morning &afternoon
S10: CHART 2: | T10: High demand in clear weather
S11: CHART 3: Weekday vs Weekend | T11: Weekday demand higher than weekend
B16: Peak usage in morning & afternoon | K16: High demand in clear weather
D17: CHART 3 | M17: SLIDER
B29: Weekday demand higher than weekend

Sheet Sheet7
A3: Row Labels | B3: Sum of cnt
A4: Clear | B4: 22139
A5: cloudy | B5: 10345
A6: Heavy Rain | B6: 26
A7: Rain | B7: 1372
A8: Grand Total | B8: 33882

Sheet Sheet8
A3: Row Labels | B3: Sum of cnt
A4: Weekday | B4: 25944
A5: Weekend | B5: 7938
A6: Grand Total | B6: 33882

Sheet Dataset1
A1: instant | B1: dteday | C1: season | D1: yr | E1: mnth | F1: hr | G1: holiday | H1: weekday | I1: weathersit | J1: temp | K1: day_type | L1: time_category | M1: weather_type | N1: cnt
A2: 1 | B2: 40544 | C2: 1 | D2: 0 | E2: 1 | F2: 0 | G2: FALSE | H2: 6 | I2: 1 | J2: 0.24 | K2: =IF(OR(H2=0,H2=6),"Weekend","Weekday") -> Weekend | L2: =IF(F2<12,"Morning",IF(F2<18,"Afternoon","Evening")) -> Morning | M2: =IF(I2=1,"Clear",IF(I2=2,"cloudy",IF(I2=3,"Rain","Heavy Rain"))) -> Clear | N2: =IFERROR(VLOOKUP(A2,Dataset2!A:Z,8,FALSE),"") -> 40
A3: 2 | B3: 40544 | C3: 1 | D3: 0 | E3: 1 | F3: 1 | G3: FALSE | H3: 6 | I3: 1 | J3: 0.22 | K3: =IF(OR(H3=0,H3=6),"Weekend","Weekday") -> Weekend | L3: =IF(F3<12,"Morning",IF(F3<18,"Afternoon","Evening")) -> Morning | M3: =IF(I3=1,"Clear",IF(I3=2,"cloudy",IF(I3=3,"Rain","Heavy Rain"))) -> Clear | N3: =IFERROR(VLOOKUP(A3,Dataset2!A:Z,8,FALSE),"") -> 32
A4: 3 | B4: 40544 | C4: 1 | D4: 0 | E4: 1 | F4: 2 | G4: FALSE | H4: 6 | I4: 1 | J4: 0.22 | K4: =IF(OR(H4=0,H4=6),"Weekend","Weekday") -> Weekend | L4: =IF(F4<12,"Morning",IF(F4<18,"Afternoon","Evening")) -> Morning | M4: =IF(I4=1,"Clear",IF(I4=2,"cloudy",IF(I4=3,"Rain","Heavy Rain"))) -> Clear | N4: =IFERROR(VLOOKUP(A4,Dataset2!A:Z,8,FALSE),"") -> 13
A5: 4 | B5: 40544 | C5: 1 | D5: 0 | E5: 1 | F5: 3 | G5: FALSE | H5: 6 | I5: 1 | J5: 0.24 | K5: =IF(OR(H5=0,H5=6),"Weekend","Weekday") -> Weekend | L5: =IF(F5<12,"Morning",IF(F5<18,"Afternoon","Evening")) -> Morning | M5: =IF(I5=1,"Clear",IF(I5=2,"cloudy",IF(I5=3,"Rain","Heavy Rain"))) -> Clear | N5: =IFERROR(VLOOKUP(A5,Dataset2!A:Z,8,FALSE),"") -> 1
A6: 5 | B6: 40544 | C6: 1 | D6: 0 | E6: 1 | F6: 4 | G6: FALSE | H6: 6 | I6: 1 | J6: 0.24 | K6: =IF(OR(H6=0,H6=6),"Weekend","Weekday") -> Weekend | L6: =IF(F6<12,"Morning",IF(F6<18,"Afternoon","Evening")) -> Morning | M6: =IF(I6=1,"Clear",IF(I6=2,"cloudy",IF(I6=3,"Rain","Heavy Rain"))) -> Clear | N6: =IFERROR(VLOOKUP(A6,Dataset2!A:Z,8,FALSE),"") -> 1
A7: 6 | B7: 40544 | C7: 1 | D7: 0 | E7: 1 | F7: 5 | G7: FALSE | H7: 6 | I7: 2 | J7: 0.24 | K7: =IF(OR(H7=0,H7=6),"Weekend","Weekday") -> Weekend | L7: =IF(F7<12,"Morning",IF(F7<18,"Afternoon","Evening")) -> Morning | M7: =IF(I7=1,"Clear",IF(I7=2,"cloudy",IF(I7=3,"Rain","Heavy Rain"))) -> cloudy | N7: =IFERROR(VLOOKUP(A7,Dataset2!A:Z,8,FALSE),"") -> 2
A8: 7 | B8: 40544 | C8: 1 | D8: 0 | E8: 1 | F8: 6 | G8: FALSE | H8: 6 | I8: 1 | J8: 0.22 | K8: =IF(OR(H8=0,H8=6),"Weekend","Weekday") -> Weekend | L8: =IF(F8<12,"Morning",IF(F8<18,"Afternoon","Evening")) -> Morning | M8: =IF(I8=1,"Clear",IF(I8=2,"cloudy",IF(I8=3,"Rain","Heavy Rain"))) -> Clear | N8: =IFERROR(VLOOKUP(A8,Dataset2!A:Z,8,FALSE),"") -> 3
A9: 8 | B9: 40544 | C9: 1 | D9: 0 | E9: 1 | F9: 7 | G9: FALSE | H9: 6 | I9: 1 | J9: 0.2 | K9: =IF(OR(H9=0,H9=6),"Weekend","Weekday") -> Weekend | L9: =IF(F9<12,"Morning",IF(F9<18,"Afternoon","Evening")) -> Morning | M9: =IF(I9=1,"Clear",IF(I9=2,"cloudy",IF(I9=3,"Rain","Heavy Rain"))) -> Clear | N9: =IFERROR(VLOOKUP(A9,Dataset2!A:Z,8,FALSE),"") -> 8
A10: 9 | B10: 40544 | C10: 1 | D10: 0 | E10: 1 | F10: 8 | G10: FALSE | H10: 6 | I10: 1 | J10: 0.24 | K10: =IF(OR(H10=0,H10=6),"Weekend","Weekday") -> Weekend | L10: =IF(F10<12,"Morning",IF(F10<18,"Afternoon","Evening")) -> Morning | M10: =IF(I10=1,"Clear",IF(I10=2,"cloudy",IF(I10=3,"Rain","Heavy Rain"))) -> Clear | N10: =IFERROR(VLOOKUP(A10,Dataset2!A:Z,8,FALSE),"") -> 14
A11: 10 | B11: 40544 | C11: 1 | D11: 0 | E11: 1 | F11: 9 | G11: FALSE | H11: 6 | I11: 1 | J11: 0.32 | K11: =IF(OR(H11=0,H11=6),"Weekend","Weekday") -> Weekend | L11: =IF(F11<12,"Morning",IF(F11<18,"Afternoon","Evening")) -> Morning | M11: =IF(I11=1,"Clear",IF(I11=2,"cloudy",IF(I11=3,"Rain","Heavy Rain"))) -> Clear | N11: =IFERROR(VLOOKUP(A11,Dataset2!A:Z,8,FALSE),"") -> 36
A12: 11 | B12: 40544 | C12: 1 | D12: 0 | E12: 1 | F12: 10 | G12: FALSE | H12: 6 | I12: 1 | J12: 0.38 | K12: =IF(OR(H12=0,H12=6),"Weekend","Weekday") -> Weekend | L12: =IF(F12<12,"Morning",IF(F12<18,"Afternoon","Evening")) -> Morning | M12: =IF(I12=1,"Clear",IF(I12=2,"cloudy",IF(I12=3,"Rain","Heavy Rain"))) -> Clear | N12: =IFERROR(VLOOKUP(A12,Dataset2!A:Z,8,FALSE),"") -> 56
A13: 12 | B13: 40544 | C13: 1 | D13: 0 | E13: 1 | F13: 11 | G13: FALSE | H13: 6 | I13: 1 | J13: 0.36 | K13: =IF(OR(H13=0,H13=6),"Weekend","Weekday") -> Weekend | L13: =IF(F13<12,"Morning",IF(F13<18,"Afternoon","Evening")) -> Morning | M13: =IF(I13=1,"Clear",IF(I13=2,"cloudy",IF(I13=3,"Rain","Heavy Rain"))) -> Clear | N13: =IFERROR(VLOOKUP(A13,Dataset2!A:Z,8,FALSE),"") -> 84
... A611: 610 | B611: 40571 | C611: 1 | D611: 0 | E611: 1 | F611: 15 | G611: FALSE | H611: 5 | I611: 2 | J611: 0.2 | K611: =IF(OR(H611=0,H611=6),"Weekend","Weekday") -> Weekday | L611: =IF(F611<12,"Morning",IF(F611<18,"Afternoon","Evening")) -> Afternoon | M611: =IF(I611=1,"Clear",IF(I611=2,"cloudy",IF(I611=3,"Rain","Heavy Rain"))) -> cloudy | N611: =IFERROR(VLOOKUP(A611,Dataset2!A:Z,8,FALSE),"")
